<?xml version="1.0" encoding="utf-8"?>
<!-- This URDF was automatically created by SolidWorks to URDF Exporter! Originally created by Stephen Brawner (brawner@gmail.com) 
     Commit Version: 1.6.0-1-g15f4949  Build Version: 1.6.7594.29634
     For more information, please see http://wiki.ros.org/sw_urdf_exporter -->
<robot
  name="mobile_robot">
  <link
    name="base_link">
    <inertial>
      <origin
        xyz="2.2942E-09 2.7821E-09 0.081848"
        rpy="0 0 0" />
      <mass
        value="1.0999" />
      <inertia
        ixx="0.018561"
        ixy="-4.5546E-10"
        ixz="-2.8662E-12"
        iyy="0.013478"
        iyz="-3.4644E-12"
        izz="0.01975" />
    </inertial>
    <visual>
      <origin
        xyz="0 0 0"
        rpy="0 0 0" />
      <geometry>
        <mesh
          filename="package://mobile_robot/meshes/base_link.STL" />
      </geometry>
      <material
        name="">
        <color
          rgba="0.8 0.8 0.8 1" />
      </material>
    </visual>
    <collision>
      <origin
        xyz="0 0 0"
        rpy="0 0 0" />
      <geometry>
        <mesh
          filename="package://mobile_robot/meshes/base_link.STL" />
      </geometry>
    </collision>
  </link>
  <link
    name="left_wheel">
    <inertial>
      <origin
        xyz="-0.00019487 0 0"
        rpy="0 0 0" />
      <mass
        value="0.35316" />
      <inertia
        ixx="0.00057446"
        ixy="-1.0541E-20"
        ixz="-1.2007E-21"
        iyy="0.00030435"
        iyz="-1.6186E-20"
        izz="0.00030435" />
    </inertial>
    <visual>
      <origin
        xyz="0 0 0"
        rpy="0 0 0" />
      <geometry>
        <mesh
          filename="package://mobile_robot/meshes/wheel.STL" />
      </geometry>
      <material
        name="">
        <color
          rgba="0.2 0.2 0.2 1" />
      </material>
    </visual>
    <collision>
      <origin
        xyz="0 0 0"
        rpy="0 0 0" />
      <geometry>
        <mesh
          filename="package://mobile_robot/meshes/wheel.STL" />
      </geometry>
    </collision>
  </link>
  <joint
    name="left_wheel_joint"
    type="continuous">
    <origin
      xyz="-0.102 0 0.02"
      rpy="-1.5708 0 3.1416" />
    <parent
      link="base_link" />
    <child
      link="left_wheel" />
    <axis
      xyz="1 0 0" />
    <limit
      effort="0.1"
      velocity="10" />
    <dynamics
      damping="5"
      friction="0.1" />
  </joint>
  <link
    name="right_wheel">
    <inertial>
      <origin
        xyz="-0.00019487 0 -5.5511E-17"
        rpy="0 0 0" />
      <mass
        value="0.35316" />
      <inertia
        ixx="0.00057446"
        ixy="-1.6127E-20"
        ixz="4.2409E-21"
        iyy="0.00030435"
        iyz="7.4539E-20"
        izz="0.00030435" />
    </inertial>
    <visual>
      <origin
        xyz="0 0 0"
        rpy="0 0 0" />
      <geometry>
        <mesh
          filename="package://mobile_robot/meshes/wheel.STL" />
      </geometry>
      <material
        name="">
        <color
          rgba="0.2 0.2 0.2 1" />
      </material>
    </visual>
    <collision>
      <origin
        xyz="0 0 0"
        rpy="0 0 0" />
      <geometry>
        <mesh
          filename="package://mobile_robot/meshes/wheel.STL" />
      </geometry>
    </collision>
  </link>
  <joint
    name="right_wheel_joint"
    type="continuous">
    <origin
      xyz="0.102 0 0.02"
      rpy="-1.5708 0 3.1416" />
    <parent
      link="base_link" />
    <child
      link="right_wheel" />
    <axis
      xyz="1 0 0" />
    <limit
      effort="0.1"
      velocity="10" />
    <dynamics
      damping="0.5"
      friction="0.1" />
  </joint>
  <link
    name="caster_front">
    <inertial>
      <origin
        xyz="0.0024842 1.8972E-05 -0.0069742"
        rpy="0 0 0" />
      <mass
        value="0.0086939" />
      <inertia
        ixx="6.8617E-07"
        ixy="-7.4905E-10"
        ixz="1.1563E-07"
        iyy="5.8177E-07"
        iyz="1.5722E-09"
        izz="6.2943E-07" />
    </inertial>
    <visual>
      <origin
        xyz="0 0 0"
        rpy="0 0 0" />
      <geometry>
        <mesh
          filename="package://mobile_robot/meshes/revo_caster.STL" />
      </geometry>
      <material
        name="">
        <color
          rgba="0.69804 0.69804 0.69804 1" />
      </material>
    </visual>
    <collision>
      <origin
        xyz="0 0 0"
        rpy="0 0 0" />
      <geometry>
        <mesh
          filename="package://mobile_robot/meshes/revo_caster.STL" />
      </geometry>
    </collision>
  </link>
  <joint
    name="caster_front_joint"
    type="continuous">
    <origin
      xyz="0 0.15 -0.0038"
      rpy="0 0 -1.584" />
    <parent
      link="base_link" />
    <child
      link="caster_front" />
    <axis
      xyz="0 0 1" />
    <dynamics
      damping="0.2"
      friction="0.1" />
  </joint>
  <link
    name="caster_front_wheel">
    <inertial>
      <origin
        xyz="-7.9484E-08 -2.018E-07 5.7893E-08"
        rpy="0 0 0" />
      <mass
        value="0.0039368" />
      <inertia
        ixx="1.4244E-07"
        ixy="7.0479E-12"
        ixz="1.0503E-11"
        iyy="1.4236E-07"
        iyz="1.0861E-11"
        izz="2.1534E-07" />
    </inertial>
    <visual>
      <origin
        xyz="0 0 0"
        rpy="0 0 0" />
      <geometry>
        <mesh
          filename="package://mobile_robot/meshes/caster_wheel.STL" />
      </geometry>
      <material
        name="">
        <color
          rgba="0.2 0.2 0.2 1" />
      </material>
    </visual>
    <collision>
      <origin
        xyz="0 0 0"
        rpy="0 0 0" />
      <geometry>
        <mesh
          filename="package://mobile_robot/meshes/caster_wheel.STL" />
      </geometry>
    </collision>
  </link>
  <joint
    name="caster_front_wheel_joint"
    type="continuous">
    <origin
      xyz="0.007 0 -0.01652"
      rpy="1.5708 0 -3.1416" />
    <parent
      link="caster_front" />
    <child
      link="caster_front_wheel" />
    <axis
      xyz="0 0 1" />
    <dynamics
      damping="0.2"
      friction="0.1" />
  </joint>
  <link
    name="caster_back">
    <inertial>
      <origin
        xyz="0 0 0"
        rpy="0 0 0" />
      <mass
        value="0" />
      <inertia
        ixx="0"
        ixy="0"
        ixz="0"
        iyy="0"
        iyz="0"
        izz="0" />
    </inertial>
    <visual>
      <origin
        xyz="0 0 0"
        rpy="0 0 0" />
      <geometry>
        <mesh
          filename="package://mobile_robot/meshes/revo_caster.STL" />
      </geometry>
      <material
        name="">
        <color
          rgba="1 1 1 1" />
      </material>
    </visual>
    <collision>
      <origin
        xyz="0 0 0"
        rpy="0 0 0" />
      <geometry>
        <mesh
          filename="package://mobile_robot/meshes/revo_caster.STL" />
      </geometry>
    </collision>
  </link>
  <joint
    name="caster_back_joint"
    type="continuous">
    <origin
      xyz="0 -0.15 -0.0038"
      rpy="0 0 1.5528" />
    <parent
      link="base_link" />
    <child
      link="caster_back" />
    <axis
      xyz="0 0 1" />
    <dynamics
      damping="0.2"
      friction="0.1" />
  </joint>
  <link
    name="caster_back_wheel">
    <inertial>
      <origin
        xyz="-7.9885E-08 -2.019E-07 5.7873E-08"
        rpy="0 0 0" />
      <mass
        value="0.0039368" />
      <inertia
        ixx="1.4244E-07"
        ixy="7.0526E-12"
        ixz="1.0503E-11"
        iyy="1.4236E-07"
        iyz="1.0862E-11"
        izz="2.1534E-07" />
    </inertial>
    <visual>
      <origin
        xyz="0 0 0"
        rpy="0 0 0" />
      <geometry>
        <mesh
          filename="package://mobile_robot/meshes/caster_wheel.STL" />
      </geometry>
      <material
        name="">
        <color
          rgba="0.2 0.2 0.2 1" />
      </material>
    </visual>
    <collision>
      <origin
        xyz="0 0 0"
        rpy="0 0 0" />
      <geometry>
        <mesh
          filename="package://mobile_robot/meshes/caster_wheel.STL" />
      </geometry>
    </collision>
  </link>
  <joint
    name="caster_back_wheel_joint"
    type="continuous">
    <origin
      xyz="0.007 0 -0.01652"
      rpy="1.5708 0 3.1416" />
    <parent
      link="caster_back" />
    <child
      link="caster_back_wheel" />
    <axis
      xyz="0 0 1" />
    <dynamics
      damping="0.2"
      friction="0.1" />
  </joint>
</robot>